Stopping server.
Starting server on port 5000/udp
Using selector: EpollSelector
Starting server on port 8443/tcp, use <Ctrl-C> to stop
{'timestamp': '2022-06-01T18:35:04.990479', 'src_ip': '192.241.216.50', 'payload_printable': '"GET / HTTP/1.1" 200 -'}
{'timestamp': '2022-06-01T18:35:07.993220', 'src_ip': '192.241.216.50', 'payload_printable': 'Request timed out: timeout('The read operation timed out')'}
{'timestamp': '2022-06-01T19:16:59.369300', 'src_ip': '45.93.16.70', 'payload_printable': '"GET /WebMgmtEE/WebManagement.html HTTP/1.1" 404 -'}
{'timestamp': '2022-06-01T19:17:02.373157', 'src_ip': '45.93.16.70', 'payload_printable': 'Request timed out: timeout('The read operation timed out')'}
{'timestamp': '2022-06-01T19:37:11.328235', 'src_ip': '183.136.225.42', 'payload_printable': '"GET / HTTP/1.1" 200 -'}
{'timestamp': '2022-06-01T19:37:14.331275', 'src_ip': '183.136.225.42', 'payload_printable': 'Request timed out: timeout('The read operation timed out')'}
{'timestamp': '2022-06-01T19:37:41.172388', 'src_ip': '183.136.225.42', 'payload_printable': '"GET /favicon.ico HTTP/1.1" 404 -'}
{'timestamp': '2022-06-01T19:37:42.955778', 'src_ip': '183.136.225.42', 'payload_printable': '"GET /robots.txt HTTP/1.1" 404 -'}
{'timestamp': '2022-06-01T20:41:32.332867', 'src_ip': '107.189.11.67', 'payload_printable': '"GET /manager/html HTTP/1.1" 404 -'}
unsupported packet
Exception in callback _SelectorDatagramTransport._read_ready()
handle: <Handle _SelectorDatagramTransport._read_ready()>
Traceback (most recent call last):
  File "/tmp/ciscoasa/ike_server.py", line 35, in datagram_received
    packet = ike.parse_packet(data=data)
  File "/usr/lib/python3.9/site-packages/ike/protocol.py", line 327, in parse_packet
    packet.exchange_type = const.ExchangeType(exchange_type)
  File "/usr/lib/python3.9/enum.py", line 384, in __call__
    return cls.__new__(cls, value)
  File "/usr/lib/python3.9/enum.py", line 702, in __new__
    raise ve_exc
ValueError: 49 is not a valid ExchangeType

During handling of the above exception, another exception occurred:

Traceback (most recent call last):
  File "/usr/lib/python3.9/asyncio/events.py", line 80, in _run
    self._context.run(self._callback, *self._args)
  File "/usr/lib/python3.9/asyncio/selector_events.py", line 1029, in _read_ready
    self._protocol.datagram_received(data, addr)
  File "/tmp/ciscoasa/ike_server.py", line 57, in datagram_received
    hpfl.log('debug', 'IKE unsupported packet')
NameError: name 'hpfl' is not defined
